<?xml version="1.0" ?>
<robot name="turtlebot3_waffle_pi" xmlns:xacro="http://ros.org/wiki/xacro">
  <xacro:include filename="$(find turtlebot3_description)/urdf/common_properties.xacro"/>
  <xacro:include filename="$(find turtlebot3_description)/urdf/turtlebot3_waffle_pi.gazebo.xacro"/>

  <link name="base_footprint"/>

  <joint name="base_joint" type="fixed">
    <parent link="base_footprint"/>
    <child link="base_link" />
    <origin xyz="0 0 0.010" rpy="0 0 0"/>
  </joint>

  <link name="base_link">
    <visual>
      <origin xyz="-0.064 0 0.0" rpy="0 0 0"/>
      <geometry>
        <mesh filename="package://turtlebot3_description/meshes/bases/waffle_pi_base.stl" scale="0.001 0.001 0.001"/>
      </geometry>
      <material name="light_black"/>
    </visual>

    <collision>
      <origin xyz="-0.064 0 0.047" rpy="0 0 0"/>
      <geometry>
        <box size="0.266 0.266 0.094"/>
      </geometry>
    </collision>

    <inertial>
      <origin xyz="0 0 0" rpy="0 0 0"/>
      <mass value="1.3729096e+00"/>
      <inertia ixx="8.7002718e-03" ixy="-4.7576583e-05" ixz="1.1160499e-04"
               iyy="8.6195418e-03" iyz="-3.5422299e-06"
               izz="1.4612727e-02" />
    </inertial>
  </link>

  <joint name="wheel_left_joint" type="continuous">
    <parent link="base_link"/>
    <child link="wheel_left_link"/>
    <origin xyz="0.0 0.144 0.023" rpy="-1.57 0 0"/>
    <axis xyz="0 0 1"/>
  </joint>

  <link name="wheel_left_link">
    <visual>
      <origin xyz="0 0 0" rpy="1.57 0 0"/>
      <geometry>
        <mesh filename="package://turtlebot3_description/meshes/wheels/left_tire.stl" scale="0.001 0.001 0.001"/>
      </geometry>
      <material name="dark"/>
    </visual>

    <collision>
      <origin xyz="0 0 0" rpy="0 0 0"/>
      <geometry>
        <cylinder length="0.018" radius="0.033"/>
      </geometry>
    </collision>

    <inertial>
      <origin xyz="0 0 0" />
      <mass value="2.8498940e-02" />
      <inertia ixx="1.1175580e-05" ixy="-4.2369783e-11" ixz="-5.9381719e-09"
               iyy="1.1192413e-05" iyz="-1.4400107e-11"
               izz="2.0712558e-05" />
      </inertial>
  </link>

  <joint name="wheel_right_joint" type="continuous">
    <parent link="base_link"/>
    <child link="wheel_right_link"/>
    <origin xyz="0.0 -0.144 0.023" rpy="-1.57 0 0"/>
    <axis xyz="0 0 1"/>
  </joint>

  <link name="wheel_right_link">
    <visual>
      <origin xyz="0 0 0" rpy="1.57 0 0"/>
      <geometry>
        <mesh filename="package://turtlebot3_description/meshes/wheels/right_tire.stl" scale="0.001 0.001 0.001"/>
      </geometry>
      <material name="dark"/>
    </visual>

    <collision>
      <origin xyz="0 0 0" rpy="0 0 0"/>
      <geometry>
        <cylinder length="0.018" radius="0.033"/>
      </geometry>
    </collision>

    <inertial>
      <origin xyz="0 0 0" />
      <mass value="2.8498940e-02" />
      <inertia ixx="1.1175580e-05" ixy="-4.2369783e-11" ixz="-5.9381719e-09"
               iyy="1.1192413e-05" iyz="-1.4400107e-11"
               izz="2.0712558e-05" />
      </inertial>
  </link>

  <joint name="caster_back_right_joint" type="fixed">
    <parent link="base_link"/>
    <child link="caster_back_right_link"/>
    <origin xyz="-0.177 -0.064 -0.004" rpy="-1.57 0 0"/>
  </joint>

  <link name="caster_back_right_link">
    <collision>
      <origin xyz="0 0.001 0" rpy="0 0 0"/>
      <geometry>
        <box size="0.030 0.009 0.020"/>
      </geometry>
    </collision>

    <inertial>
      <origin xyz="0 0 0" />
      <mass value="0.005" />
      <inertia ixx="0.001" ixy="0.0" ixz="0.0"
               iyy="0.001" iyz="0.0"
               izz="0.001" />
    </inertial>
  </link>

  <joint name="caster_back_left_joint" type="fixed">
    <parent link="base_link"/>
    <child link="caster_back_left_link"/>
    <origin xyz="-0.177 0.064 -0.004" rpy="-1.57 0 0"/>
  </joint>

  <link name="caster_back_left_link">
    <collision>
      <origin xyz="0 0.001 0" rpy="0 0 0"/>
      <geometry>
        <box size="0.030 0.009 0.020"/>
      </geometry>
    </collision>

    <inertial>
      <origin xyz="0 0 0" />
      <mass value="0.005" />
      <inertia ixx="0.001" ixy="0.0" ixz="0.0"
               iyy="0.001" iyz="0.0"
               izz="0.001" />
    </inertial>
  </link>

  <joint name="imu_joint" type="fixed">
    <parent link="base_link"/>
    <child link="imu_link"/>
    <origin xyz="0.0 0 0.068" rpy="0 0 0"/>
  </joint>

  <link name="imu_link"/>

  <joint name="scan_joint" type="fixed">
    <parent link="base_link"/>
    <child link="base_scan"/>
    <origin xyz="-0.064 0 0.122" rpy="0 0 0"/>
  </joint>

  <link name="base_scan">
    <visual>
      <origin xyz="0 0 0.0" rpy="0 0 0"/>
      <geometry>
        <mesh filename="package://turtlebot3_description/meshes/sensors/lds.stl" scale="0.001 0.001 0.001"/>
      </geometry>
      <material name="dark"/>
    </visual>

    <collision>
      <origin xyz="0.015 0 -0.0065" rpy="0 0 0"/>
      <geometry>
        <cylinder length="0.0315" radius="0.055"/>
      </geometry>
    </collision>

    <inertial>
      <mass value="0.114" />
      <origin xyz="0 0 0" />
      <inertia ixx="0.001" ixy="0.0" ixz="0.0"
               iyy="0.001" iyz="0.0"
               izz="0.001" />
    </inertial>
  </link>

  <!-- <joint name="camera_joint" type="fixed">
    <origin xyz="0.073 -0.011 0.084" rpy="0 0 0"/>
    <parent link="base_link"/>
    <child link="camera_link"/>
  </joint>

  <link name="camera_link">
    <collision>
      <origin xyz="0.005 0.011 0.013" rpy="0 0 0"/>
      <geometry>
        <box size="0.015 0.030 0.027"/>
      </geometry>
    </collision>
  </link>

  <joint name="camera_rgb_joint" type="fixed">
    <origin xyz="0.003 0.011 0.009" rpy="0 0 0"/>
    <parent link="camera_link"/>
    <child link="camera_rgb_frame"/>
  </joint>
  <link name="camera_rgb_frame"/>

  <joint name="camera_rgb_optical_joint" type="fixed">
    <origin xyz="0 0 0" rpy="-1.57 0 -1.57"/>
    <parent link="camera_rgb_frame"/>
    <child link="camera_rgb_optical_frame"/>
  </joint>
  <link name="camera_rgb_optical_frame"/> -->
<!-- KINECT V2 -->
  <joint name="kinect_rgb_joint" type="fixed">
          <origin xyz="0.3 0 0.3" rpy="0 0 0" />
            <parent link="kinect_link"/>
            <child link="kinect_rgb_frame" />
      </joint>

      <link name="kinect_rgb_frame">
            <inertial>
                <mass value="0.001" />
                <origin xyz="0 0 0" />
                <inertia ixx="0.0001" ixy="0.0" ixz="0.0" iyy="0.0001" iyz="0.0" izz="0.0001" />
            </inertial>
      </link>

      <joint name="kinect_rgb_optical_joint" type="fixed">
            <origin xyz="0 0 0" rpy="-1.570796326795 0 -1.570796326795" />
            <parent link="kinect_rgb_frame" />
            <child link="kinect_rgb_optical_frame" />
      </joint>

      <link name="kinect_rgb_optical_frame">
            <inertial>
                <mass value="0.001" />
                <origin xyz="0 0 0" />
                <inertia ixx="0.0001" ixy="0.0" ixz="0.0" iyy="0.0001" iyz="0.0" izz="0.0001" />
            </inertial>
      </link>

      <joint name="kinect_joint" type="fixed">
          <origin xyz="0.1 0.0 0.01" rpy="0 0 0"/>
          <parent link="base_link"/>
          <child link="kinect_link"/>
      </joint>

      <link name="kinect_link">
            <visual>
                <origin xyz="0 0 0" rpy="0 0 1.570796326795"/>
                <geometry>
                          <mesh filename="package://model_robot/meshes/sensors/kinectv2.dae"/>
                </geometry>
                <!-- <material name="black"/> -->
            </visual>
            <collision>

                      <origin xyz="0.0471 0.125 0.03225" rpy="0 0 0"/>
                      <geometry>
                          <box size="0.0943 0.25 0.0645"/>
                      </geometry>

                
            </collision>
            <inertial>
                <mass value="0.001" />
                <origin xyz="0 0 0" />
                <inertia ixx="0.0001" ixy="0.0" ixz="0.0" iyy="0.0001" iyz="0.0" izz="0.0001" />
            </inertial>
      </link>

      <!-- The fixed joints & links below are usually published by static_transformers launched by the OpenNi launch
      files. However, for Gazebo simulation we need them, so we add them here.
      (Hence, don't publish them additionally!) -->
      <joint name="kinect_depth_joint" type="fixed">
            <origin xyz="0 0 0" rpy="0 0 0" />
            <parent link="kinect_link" />
            <child link="kinect_depth_frame" />
      </joint>

      <link name="kinect_depth_frame">
            <inertial>
                <mass value="0.001" />
                <origin xyz="0 0 0" />
                <inertia ixx="0.0001" ixy="0.0" ixz="0.0" iyy="0.0001" iyz="0.0" izz="0.0001" />
            </inertial>
      </link>

      <joint name="kinect_depth_optical_joint" type="fixed">
            <origin xyz="0 0 0" rpy="1.570796326795 0 1.570796326795" />
            <parent link="kinect_depth_frame" />
            <child link="kinect_depth_optical_frame" />
      </joint>
      <!-- 3.14159265359 -->
      <link name="kinect_depth_optical_frame">
            <inertial>
                <mass value="0.001" />
                <origin xyz="0 0 0" />
                <inertia ixx="0.0001" ixy="0.0" ixz="0.0" iyy="0.0001" iyz="0.0" izz="0.0001" />
            </inertial>
      </link>

      <!-- Kinect sensor for simulation -->
      <!-- <sensor_kinectv2_gazebo/> -->
      <!-- <xacro:color_gazebo parent="kinect_link" color="orange"/> -->

      <gazebo reference="kinect_link">
            <sensor type="depth" name="kinect_sensor">
                <always_on>true</always_on>
                <visualize>true</visualize>
                <update_rate>5.0</update_rate>

                <camera>
                      <horizontal_fov>1.047197551</horizontal_fov>
                      <image>
                          <format>R8G8B8</format>
                          <width>144</width>
                          <height>176</height>
                      </image>
                      <clip>
                          <near>0.05</near>
                          <far>8.0</far>
                      </clip>
                </camera>

                <plugin name="kinect_controller" filename="libgazebo_ros_openni_kinect.so">
                      <cameraName>kinect</cameraName>
                      <alwaysOn>true</alwaysOn>
                      <visualize>true</visualize>
                      <updateRate>10</updateRate>
                      <imageTopicName>rgb/image_raw</imageTopicName>
                      <depthImageTopicName>depth/image_raw</depthImageTopicName>
                      <pointCloudTopicName>depth/points</pointCloudTopicName>
                      <cameraInfoTopicName>rgb/camera_info</cameraInfoTopicName>
                      <depthImageCameraInfoTopicName>depth/camera_info</depthImageCameraInfoTopicName>
                      <frameName>base_link</frameName>
                      <baseline>0.1</baseline>
                      <distortion_k1>0.0</distortion_k1>
                      <distortion_k2>0.0</distortion_k2>
                      <distortion_k3>0.0</distortion_k3>
                      <distortion_t1>0.0</distortion_t1>
                      <distortion_t2>0.0</distortion_t2>
                      <pointCloudCutoff>0.4</pointCloudCutoff>
                      <pointCloudCutoffMax>5.0</pointCloudCutoffMax>
                </plugin>
            </sensor>
      </gazebo>
</robot>
